<mujoco model="spot_dance_full">
    <compiler angle="degree" coordinate="local"/>
    <option gravity="0 0 -9.81" integrator="RK4" timestep="0.002"/>

    <asset>
        <mesh name="spot_body" file="assets/spot/spot_body.obj"/>
        <mesh name="spot_head" file="assets/spot/spot_head.obj"/>
        <mesh name="spot_leg_upper" file="assets/spot/spot_leg_upper.obj"/>
        <mesh name="spot_leg_lower" file="assets/spot/spot_leg_lower.obj"/>
    </asset>

    <worldbody>
        <!-- Ground -->
        <geom name="floor" type="plane" size="5 5 0.1" rgba="0.8 0.8 0.8 1"/>

        <!-- Spot Base -->
        <body name="spot_base" pos="0 0 0.4">
            <freejoint/>
            <geom type="mesh" mesh="spot_body" rgba="1 1 0 1"/> <!-- Yellow body -->

            <!-- Spot Head -->
            <body name="spot_head" pos="0.2 0 0.1">
                <geom type="mesh" mesh="spot_head" rgba="0.3 0.3 0.3 1"/>
            </body>

            <!-- Front Left Leg -->
            <body name="front_left_leg" pos="0.25 0.15 0">
                <joint name="front_left_abad" type="hinge" axis="1 0 0"/>
                <body name="front_left_hip" pos="0 0 -0.05">
                    <joint name="front_left_hip" type="hinge" axis="0 1 0"/>
                    <body name="front_left_knee" pos="0 0 -0.25">
                        <joint name="front_left_knee" type="hinge" axis="0 1 0"/>
                        <geom type="mesh" mesh="spot_leg_upper" pos="0 0 -0.125" rgba="0 0 0 1"/>
                        <geom type="mesh" mesh="spot_leg_lower" pos="0 0 -0.25" rgba="0 0 0 1"/>
                    </body>
                </body>
            </body>

            <!-- Front Right Leg -->
            <body name="front_right_leg" pos="0.25 -0.15 0">
                <joint name="front_right_abad" type="hinge" axis="1 0 0"/>
                <body name="front_right_hip" pos="0 0 -0.05">
                    <joint name="front_right_hip" type="hinge" axis="0 1 0"/>
                    <body name="front_right_knee" pos="0 0 -0.25">
                        <joint name="front_right_knee" type="hinge" axis="0 1 0"/>
                        <geom type="mesh" mesh="spot_leg_upper" pos="0 0 -0.125" rgba="0 0 0 1"/>
                        <geom type="mesh" mesh="spot_leg_lower" pos="0 0 -0.25" rgba="0 0 0 1"/>
                    </body>
                </body>
            </body>

            <!-- Back Left Leg -->
            <body name="back_left_leg" pos="-0.25 0.15 0">
                <joint name="back_left_abad" type="hinge" axis="1 0 0"/>
                <body name="back_left_hip" pos="0 0 -0.05">
                    <joint name="back_left_hip" type="hinge" axis="0 1 0"/>
                    <body name="back_left_knee" pos="0 0 -0.25">
                        <joint name="back_left_knee" type="hinge" axis="0 1 0"/>
                        <geom type="mesh" mesh="spot_leg_upper" pos="0 0 -0.125" rgba="0 0 0 1"/>
                        <geom type="mesh" mesh="spot_leg_lower" pos="0 0 -0.25" rgba="0 0 0 1"/>
                    </body>
                </body>
            </body>

            <!-- Back Right Leg -->
            <body name="back_right_leg" pos="-0.25 -0.15 0">
                <joint name="back_right_abad" type="hinge" axis="1 0 0"/>
                <body name="back_right_hip" pos="0 0 -0.05">
                    <joint name="back_right_hip" type="hinge" axis="0 1 0"/>
                    <body name="back_right_knee" pos="0 0 -0.25">
                        <joint name="back_right_knee" type="hinge" axis="0 1 0"/>
                        <geom type="mesh" mesh="spot_leg_upper" pos="0 0 -0.125" rgba="0 0 0 1"/>
                        <geom type="mesh" mesh="spot_leg_lower" pos="0 0 -0.25" rgba="0 0 0 1"/>
                    </body>
                </body>
            </body>

        </body>
    </worldbody>

    <actuator>
        <!-- Motors: 12 motors (abad, hip, knee) -->
        <motor joint="front_left_abad" ctrlrange="-1 1" gear="100"/>
        <motor joint="front_left_hip" ctrlrange="-1 1" gear="100"/>
        <motor joint="front_left_knee" ctrlrange="-1 1" gear="100"/>

        <motor joint="front_right_abad" ctrlrange="-1 1" gear="100"/>
        <motor joint="front_right_hip" ctrlrange="-1 1" gear="100"/>
        <motor joint="front_right_knee" ctrlrange="-1 1" gear="100"/>

        <motor joint="back_left_abad" ctrlrange="-1 1" gear="100"/>
        <motor joint="back_left_hip" ctrlrange="-1 1" gear="100"/>
        <motor joint="back_left_knee" ctrlrange="-1 1" gear="100"/>

        <motor joint="back_right_abad" ctrlrange="-1 1" gear="100"/>
        <motor joint="back_right_hip" ctrlrange="-1 1" gear="100"/>
        <motor joint="back_right_knee" ctrlrange="-1 1" gear="100"/>
    </actuator>
</mujoco>

